{"version":3,"sources":["../../../src/client/components/unstable-rethrow.ts"],"sourcesContent":["import { isDynamicUsageError } from '../../export/helpers/is-dynamic-usage-error'\nimport { isPostpone } from '../../server/lib/router-utils/is-postpone'\nimport { isBailoutToCSRError } from '../../shared/lib/lazy-dynamic/bailout-to-csr'\nimport { isNextRouterError } from './is-next-router-error'\n\n/**\n * This function should be used to rethrow internal Next.js errors so that they can be handled by the framework.\n * When wrapping an API that uses errors to interrupt control flow, you should use this function before you do any error handling.\n * This function will rethrow the error if it is a Next.js error so it can be handled, otherwise it will do nothing.\n *\n * Read more: [Next.js Docs: `unstable_rethrow`](https://nextjs.org/docs/app/api-reference/functions/unstable_rethrow)\n */\nexport function unstable_rethrow(error: unknown): void {\n  if (\n    isNextRouterError(error) ||\n    isBailoutToCSRError(error) ||\n    isDynamicUsageError(error) ||\n    isPostpone(error)\n  ) {\n    throw error\n  }\n\n  if (error instanceof Error && 'cause' in error) {\n    unstable_rethrow(error.cause)\n  }\n}\n"],"names":["unstable_rethrow","error","isNextRouterError","isBailoutToCSRError","isDynamicUsageError","isPostpone","Error","cause"],"mappings":";;;;+BAYgBA;;;eAAAA;;;qCAZoB;4BACT;8BACS;mCACF;AAS3B,SAASA,iBAAiBC,KAAc;IAC7C,IACEC,IAAAA,oCAAiB,EAACD,UAClBE,IAAAA,iCAAmB,EAACF,UACpBG,IAAAA,wCAAmB,EAACH,UACpBI,IAAAA,sBAAU,EAACJ,QACX;QACA,MAAMA;IACR;IAEA,IAAIA,iBAAiBK,SAAS,WAAWL,OAAO;QAC9CD,iBAAiBC,MAAMM,KAAK;IAC9B;AACF"}